<mujoco model="urdf13.SLDASM">
  <compiler angle="radian"/>

  <asset>
    <mesh name="base_link" file="base_link.STL"/>
    <mesh name="left_leg" file="left_leg.STL"/>
    <mesh name="left_small_leg" file="left_small_leg.STL"/>
    <mesh name="left_wheel" file="left_wheel.STL"/>
    <mesh name="right_leg" file="right_leg.STL"/>
    <mesh name="right_small_leg" file="right_small_leg.STL"/>
    <mesh name="right_wheel" file="right_wheel.STL"/>
  </asset>

  <worldbody>
    <geom type="mesh" rgba="0.866667 0.909804 1 1" mesh="base_link"/>
    <body name="left_leg" pos="0.0774339 0.166047 0.112513">
      <inertial pos="-0.0828841 -0.00149912 -0.0243139" quat="0.5741 0.441381 0.414769 0.550961" mass="0.388175" diaginertia="0.00236878 0.00225908 0.000141684"/>
      <joint name="left_leg" pos="0 0 0" axis="0 -1 0"/>
      <geom type="mesh" rgba="0.866667 0.909804 1 1" mesh="left_leg"/>
      <body name="left_small_leg" pos="-0.205578 0.0095 -0.0629504">
        <inertial pos="0.0725246 0.00619238 -0.0267095" quat="0.38617 0.603333 0.553641 0.424669" mass="0.372625" diaginertia="0.00389492 0.00376578 0.000168691"/>
        <joint name="left_small_leg" pos="0 0 0" axis="0 1 0"/>
        <geom type="mesh" rgba="1 1 1 1" mesh="left_small_leg"/>
        <body name="left_wheel" pos="0.240044 0.03105 -0.0830362">
          <inertial pos="0.000115992 -0.00625993 -0.0001601" quat="0.633401 0.31587 0.316919 0.631341" mass="0.57689" diaginertia="0.000966912 0.000559337 0.00055726"/>
          <joint name="left_wheel" pos="0 0 0" axis="0 1 0"/>
          <geom type="mesh" rgba="0.866667 0.909804 1 1" mesh="left_wheel"/>
        </body>
      </body>
    </body>
    <body name="right_leg" pos="0.0774339 -0.186353 0.112513">
      <inertial pos="-0.0817472 0.000200232 -0.0239058" quat="0.550316 0.416042 0.44081 0.574237" mass="0.378067" diaginertia="0.00232648 0.00221764 0.000139511"/>
      <joint name="right_leg" pos="0 0 0" axis="0 1 0"/>
      <geom type="mesh" rgba="0.866667 0.909804 1 1" mesh="right_leg"/>
      <body name="right_small_leg" pos="-0.205578 -0.011 -0.0629504">
        <inertial pos="0.0723505 -0.00618089 -0.0260983" quat="0.427559 0.55206 0.600424 0.389762" mass="0.371276" diaginertia="0.00389398 0.00376225 0.000171314"/>
        <joint name="right_small_leg" pos="0 0 0" axis="0 -1 0"/>
        <geom type="mesh" rgba="1 1 1 1" mesh="right_small_leg"/>
        <body name="right_wheel" pos="0.240044 -0.04355 -0.0830362">
          <inertial pos="0.000159942 0.0187599 0.00011621" quat="0.673122 -0.213486 -0.212774 0.675321" mass="0.57689" diaginertia="0.000966912 0.000559337 0.00055726"/>
          <joint name="right_wheel" pos="0 0 0" axis="0 -1 0"/>
          <geom type="mesh" rgba="0.866667 0.909804 1 1" mesh="right_wheel"/>
        </body>
      </body>
    </body>
  </worldbody>
</mujoco>
